Workbook

Sheet Main scores
C1: Qwen2.5 | I1: Qwen3 | M1: GPT-4o-mini (no RAG)
C2: 3B | F2: 7B | I2: 4B | K2: 8B
B3: Copilot (GPT-4o-mini + RAG) | C3: Instruct | D3: Fine Tuned | E3: FT Simple Prompt | F3: Instruct | G3: Fine Tuned | H3: FT Simple Prompt | I3: Instruct | J3: Fine Tuned | K3: Instruct | L3: Fine Tuned
A4: RAGAS - Answer Correctness (GPT-4o-mini) | B4: =AVERAGE('Ragas - Answer Correctness (GPT'!D4:D45) -> 0.70747534 | C4: =AVERAGE('Ragas - Answer Correctness (GPT'!E4:E45) -> 0.45506543 | D4: =AVERAGE('Ragas - Answer Correctness (GPT'!F4:F45) -> 0.50221622 | E4: =AVERAGE('Ragas - Answer Correctness (GPT'!G4:G45) -> 0.46975804 | F4: =AVERAGE('Ragas - Answer Correctness (GPT'!H4:H45) -> 0.53343197 | G4: =AVERAGE('Ragas - Answer Correctness (GPT'!I4:I45) -> 0.48207709 | H4: =AVERAGE('Ragas - Answer Correctness (GPT'!J4:J45) -> 0.48656974 | M4: =AVERAGE('Ragas - Answer Correctness (GPT'!O4:O45) -> 0.5851107
A5: RAGAS - Answer Correctness (GPT-4) | B5: =AVERAGE(Sheet1!D5:D46) -> 0.77028349 | C5: =AVERAGE(Sheet1!E5:E46) -> 0.44366684 | D5: =AVERAGE(Sheet1!F5:F46) -> 0.53750118 | E5: =AVERAGE(Sheet1!G5:G46) -> 0.49730108 | F5: =AVERAGE(Sheet1!H5:H46) -> 0.50213987 | G5: =AVERAGE(Sheet1!I5:I46) -> 0.5000876 | H5: =AVERAGE(Sheet1!J5:J46) -> 0.49817454 | M5: =AVERAGE(Sheet1!O5:O46) -> 0.5637488
A6: RAGAS - Semantic Similarity (Ada 002) | B6: =AVERAGE('Semantic Similarity (Ada 002)'!D5:D46) -> 0.94855422 | C6: =AVERAGE('Semantic Similarity (Ada 002)'!E5:E46) -> 0.89497962 | D6: =AVERAGE('Semantic Similarity (Ada 002)'!F5:F46) -> 0.91045853 | E6: =AVERAGE('Semantic Similarity (Ada 002)'!G5:G46) -> 0.90970354 | F6: =AVERAGE('Semantic Similarity (Ada 002)'!H5:H46) -> 0.90372747 | G6: =AVERAGE('Semantic Similarity (Ada 002)'!I5:I46) -> 0.91020488 | H6: =AVERAGE('Semantic Similarity (Ada 002)'!J5:J46) -> 0.91402446 | M6: =AVERAGE('Semantic Similarity (Ada 002)'!O5:O46) -> 0.90035507

Sheet Sample Answers
E1: Qwen2.5 | K1: Qwen3 | O1: GPT-4o-mini
E2: 3B | H2: 7B | K2: 4B | M2: 8B
A3: # | B3: Question | C3: Ground truth | D3: Copilot (GPT-4o-mini + RAG) | E3: Instruct | F3: Fine Tuned | G3: FT Simple Prompt | H3: Instruct | I3: Fine Tuned | J3: FT Simple Prompt | K3: Instruct | L3: Fine Tuned | M3: Instruct | N3: Fine Tuned
A4: 1 | B4: How to deploy a webapp? | C4: To deploy a web application in Choreo, follow the steps below: 1. **Create a project**: On the organization home page, click **+ Create Project**. Enter a display name, unique name, and description for the project. Click **Create**. This creates the project and opens the project home page. 2. **Create a Web Application component**: On the project home page, click **Web Application** under **Create a Single Component**. Enter a unique name and a description for the web application. 3. **Connect to GitHub**: Go to the **GitHub** tab and click **Authorize with GitHub**. If you have not already connected your GitHub repository to Choreo, enter your GitHub credentials and select the repository. You can also paste the repository URL in the **Provide Repository URL** field to connect to it without requiring authorization. 4. **Enter the required information**: Enter the required information such as your GitHub account in the **Organization** field, repository name in the **Repository** field, and the branch name in the **Branch** field. 5. **Select Buildpack**: Select a build Buildpack (eg: NodeJS, React, Python,PHP, etc.) as the **Buildpack** and provide the necessary details (eg: Project Directory, Language Version, Port, etc.). 6. **Create the component**: Click **Create**. Choreo initializes the component with the sample implementation and opens the **Overview** page of the component. 7. **Build your web application**: In the left navigation menu, click **Build**.In the Builds pane, click **Build**. This opens the Commits pane, where you can see all the commits related to the component. Select the latest commit and click **Build**. This triggers the build process and displays the progress in the **Build Logs pane**. 8. **Deploy the web application**: In the left navigation menu, click **Deploy**. In the **Set Up** card, click **Configure and Deploy**. Click **Next** to move to the **Authentication Settings** pane. Keep the default settings and click **Deploy**. 9. **Verify the deployment**: To verify that you have successfully hosted the web application, click the **Web App URL** in the **Development** card. This takes you to the web application. | D4: To deploy a web application using Choreo, you need to create a Web Application component and connect it to a Git repository containing your web application's source code. Here’s a structured approach to do this: ### Steps to Deploy a Web Application 1. **Create a Web Application Component**: - On the project home page, click on **Web Application** under the **Create a Component** section. - Choose to **Authorize with GitHub** to connect Choreo to your GitHub account. If you haven’t connected your GitHub repository yet, you will need to enter your credentials and select the appropriate repository. Alternatively, you can use a public GitHub repository by pasting the repository URL in the provided field. 2. **Enter Repository Details**: - Fill in the following information: | **Field** | **Value** | |------------------------------|-----------------------------| | **GitHub Account** | Your account | | **GitHub Repository** | Your repository name | | **Branch** | main (or your target branch)| | **Component Directory** | The directory of your application (if applicable) | 3. **Select Buildpack and Specify Build Options**: - Choose the relevant buildpack based on your web application framework (e.g., **React**, **Angular**, or **NodeJS** for server-side applications). - Provide the necessary build command, build path, and specify the Node.js version if required: | **Field** | **Description** | |------------------------------|----------------------------| | **Build Command** | Command to build your app (e.g., `npm run build`) | | **Build Path** | Output directory (e.g., `build`) | | **Node Version** | Specify the Node.js version (e.g., `18`) | 4. **Configure Application Settings**: - Enter a unique name and description for your web application component. 5. **Create the Component**: - Click **Create**. Choreo will initialize the component with the provided settings and open the **Overview** page of the component. 6. **Build and Deploy**: - Once the component is created, Choreo should automatically generate a build pipeline for your web application and deploy it. ### Additional Notes - If you are deploying a simple static website, you can use the **Static Websites** buildpack, which doesn't trigger a build process and serves the files directly from the specified path in your repository. - If you are using a Dockerfile for a containerized application, connect a repository containing the Dockerfile and follow the appropriate build steps. For more detailed instructions, you can refer to the following documents: - [Build and Deploy a Single-Page Web Application](https://wso2.com/choreo/docs/develop-components/develop-web-applications/build-and-deploy-a-single-page-web-application/#create-a-web-application) - [Deploy Your First Static Web Application](https://wso2.com/choreo/docs/quick-start-guides/deploy-your-first-static-web-application/#step-2-create-a-web-application-component) | E4: Deploying a web app on the Choreo platform typically involves several steps, but since I don't have direct access to the Choreo environment, I will guide you through the process assuming it's similar to deploying a web application in any environment. If you need more specifics about Choreo, consider looking into the documentation available there. ### Step-by-Step Guide to Deploy a Web App #### 1. Set Up Your Development Environment Make sure your local development environment is ready. You need Node.js and NPM (Node Package Manager) installed. You can install Node.js from [nodejs.org](https://nodejs.org/). Also, make sure you have Git for version control. ```sh # Install Node.js (latest LTS release) # Open https://nodejs.org/en/ ``` #### 2. Create Your Web App You can use a text editor or IDE (Integrated Development Environment) to write your web application code. Let’s assume your web application is a simple Express.js application. Here are the steps to create one: ```js // app.js const express = require('express'); const app = express(); const PORT = process.env.PORT || 3000; app.get('/', (req, res) => { res.send('Welcome to my Web App! '); }); app.listen(PORT, () => { console.log(`App running on port ${PORT}`); }); ``` Install Express.js using npm: ```sh npm install express ``` Initialize a new Node.js project: ```sh npm init -y ``` #### 3. Commit Files Commit your changes to your Git repository: ```sh git init git add . git commit -m "Add my first web application" ``` #### 4. Push to a Version Control System If your organization has a centralized source control system, push the code to the repository: ```sh git push origin master ``` #### 5. Create an API Service (if needed) If your application needs to interact with a backend, you might be setting up an API service too. Create the necessary files, and then you can use Choreo’s API services to set this up. For instance, create an API endpoint like `users`: ```js // user.js const express = require('express'); const app = express(); app.post('/api/users', (req, res) => { const user = req.body; res.send({message: 'User created!', user}); }); app.listen(3001, () => { console.log(`User Service running on port 3001`); }); ``` Again, initialize a Node.js project, commit the changes, push to the repository, and set up your API in Choreo. #### 6. Connect Services and Consumers Using Choreo’s Dashboard and/or its CLI, connect your web app and API services. Ensure they are communicating securely with each other (using OAuth, JWT tokens, etc.). #### 7. Deploy to Choreo (Optional Step) To deploy your app to Choreo, you may want to create a choreo-app.json file if you’re using a custom solution or utilize their built-in support for automatic deployments: ```json { "deploy": { "type": "auto" } } ``` In Choreo Dashboard, go to **Projects**, create or select an existing project, and follow their deployment instructions or connect to your service. Please note, this example is a generic guide. Detailed instructions depend on the specific needs and configuration required by your web app and Choreo service integration. For further detailed steps and security configurations, please consult the Choreo documentation: . | F4: To deploy a web application on the Choreo platform, follow these steps: ### Prerequisites 1. Ensure you have the required permissions for your organization. Typically, the minimum required permissions are: **Organization Read**, **Project Read**, and **Project Write**. ### Steps to Deploy a Web Application in Choreo 1. **Create a Web Application Component**: If you already have an application connected to your Git repository, proceed to the next step. Otherwise, connect your GitHub repository to Choreo by following the [Choreo Connect GitHub Repositories](https://wso2.com/choreo/docs/develop-components/develop-web-applications/connect-github-repos-choreo/#connect-github-repos-to-choreo) guide. 2. In the left navigation menu of the Choreo Console, click **Deploy**. 3. Select your component from the list of components to view the **Deploy** page. 4. In the **Set Up** card on the **Deploy** page, ensure you have filled in the mandatory fields such as a display name, name, version, project, label, description, and build pack. 5. Click on **Deploy** to start the deployment process. The build configuration will appear once the deployment completes successfully. ### Additional Notes - Choreo automatically applies best practices like microservices architecture and follows a modular design principle. - After the initial deployment, you can update the source code, apply new configurations, or rebuild your container image when changes are made in the source code repositories linked to the respective components. For more detailed guidance, you can refer to the official documentation here: [Deploy Your First Web Application](https://wso2.com/choreo/docs/develop-components/deploy-your-first-web-application/#step-3-deploy-the-web-application). | G4: To deploy a web application in Choreo, follow these steps: 1. **Deploy an Application**: - In the Choreo Console left navigation menu, click on **Deploy**. - Select **Web Application** as the buildpack. - Enter your details for deployment, including the name and description. - Click **Configure & Deploy**. The readiness and liveness checks will be automatically configured based on the file type you selected (for example, it will check for a `index.html` file for Node.js applications). - Provide appropriate configurations depending on your application type and save them. 2. **Configure Endpoint Mapping**: - Optionally, configure an endpoint mapping if you want to customize the domain name for accessing your app. If not needed, proceed to the next step. 3. **Promote to Production**: - Click the **Production** card on the Deployment page. - Confirm that the environment label in your Docker image is set to production before proceeding. - Click **Promote** to finalize the promotion. After deploying, your web application will be accessible at its publicly routable URL. If you are using a custom domain, ensure the container name matches your CNAME alias. ### Additional Notes: - You can connect a database when promoting your web application if you have a service connected via buildpack-based microservices. - Be aware of Choreo's logging constraints; logs from your application may not be available after two days and API gateway logs from the past seven days are deleted daily. For further details and specific instructions related to configuring endpoints and promotions, you can refer to the following documentation links: - [Deploy a Single-Page Web Application](https://wso2.com/choreo/docs/develop-components/deploy-a-single-page-web-application/#step-1-deploy-the-web-application) - [Configure Endpoints](https://wso2.com/choreo/docs/develop-components/configure-endpoints/) - [Promote Your Web Application](https://wso2.com/choreo/docs/develop-components/deploy-an-application/) | H4: Deploying a web application on Choreo typically involves integrating it as a service or API within the Choreo environment. However, please note that Choreo primarily focuses on API integration, webhooks, and service management rather than hosting full web applications. If you want to host and manage a web application alongside your APIs in Choreo, you might need to use additional resources or configure your web app to be triggered by events managed within Choreo. Here's how you can deploy and manage a web app or service in Choreo: ### 1. Create a New Web App Service - **Log in to Choreo**: - Open your browser and navigate to the Choreo console URL. - Log in with your credentials. - **Create a New Service**: - In the left sidebar, click on `Services`. - Click on `Add` and select `Web App`. - **Configure Your Service**: - Fill in the required details such as `Name`, `Description`, and `Endpoint URL` (URL of your web app). - Specify the authentication method if needed (e.g., Basic Auth, OAuth). - Configure any necessary settings such as SSL, CORS, and others. ### 2. Integrate with APIs/Webhooks (Optional) - **Create an API**: - Navigate to the `APIs` section. - Click on `Create API` and fill in the required details. - Configure the API endpoints to interact with your web app. - **Integrate with Webhooks**: - Navigate to the `Webhooks` section. - Create a new webhook to trigger events (like HTTP requests) when specific conditions are met, which can then interact with your web app via its endpoint. ### 3. Manage Access Control (Authentication) - **Secure Access**: - Set up authentication and authorization for both the web app and any integrated APIs or webhooks. - You can use various authentication methods supported by Choreo, such as OAuth 2.0, Basic Auth, etc. ### 4. Test and Deploy - **Test the Web App Service**: - Use the `Tests` tab in the service details page to simulate interactions with your web app. - Ensure that the endpoints and interactions are working as expected. - **Deploy**: - Once everything is tested and configured, your web app is considered deployed in the context of Choreo. It can now be accessed and interacted with through the defined endpoints. ### Additional Considerations - **Monitoring and Observability**: - Utilize the logging and monitoring features in Choreo to track the performance and health of your web app interactions. - **Scaling and Performance**: - Configure scaling policies and performance settings if necessary to handle traffic. For more detailed steps and options, please refer to the official Choreo documentation: - [Choreo Services Documentation](https://wso2.com/library/docs/developer/products/choreo/services/) - [Choreo Webhooks Documentation](https://wso2.com/library/docs/developer/products/choreo/webhooks/) - [Choreo API Management Documentation](https://wso2.com/library/docs/developer/products/choreo/api-management/) If you need further assistance with specific configurations or advanced setups, feel free to ask! | I4: To deploy a web application using Choreo, you can follow these steps: ### Step 1: Create a New Project 1. In the Choreo Console, click on **Create**. 2. Choose the **Web Application** card. 3. Select your preferred programming language (such as Go, Java, Node.js, Python, etc.). 4. Provide a name, description, and other project details to complete the creation of your web application project. ### Step 2: Build the Web Application - Choreo automatically builds the source code you provide via a Dockerfile. It follows best practices for secure container building and provides enhanced security features for container creation. - Ensure your web application can be deployed to a specified URL, which will be part of the configuration required during deployment. ### Step 3: Deploy the Web Application - To deploy your web application, go to the **Deploy** section in the Choreo Console. - The deployment process may take some time. You will need to provide configurations for the application, such as domain and port. - After the deployment, verify the URL of your web application to ensure it's accessible. ### Additional Information - If your web application is in an HTTP service, you can invoke it directly through the URL. - For more detailed instructions, you can refer to the documentation on deploying and managing a web application: [Deploy and Manage a Web Application](https://wso2.com/choreo/docs/develop-components/deploy-and-manage-a-web-application). By following these steps, you should be able to successfully deploy your web application using Choreo. | J4: To deploy a web application in Choreo, follow these steps: 1. **Create a Web Application**: You start by creating a web application component. This involves selecting the type of web application you want to develop and configuring it within the Choreo console. For more details, refer to the documentation on creating a web application: [Develop a Web Application](https://wso2.com/choreo/docs/develop-components/develop-web-applications/). 2. **Build and Deploy the Web Application**: - Once your web application is created, navigate to the left menu and click on **Deploy**. - Under the **Build Area** section, click on **Build** to compile your application. - After a successful build, go to the **Deployment Area** section and click **Deploy**. This action will initiate the deployment of your application into the development environment. 3. **View Your Application**: After a successful deployment, you can access your application via the URL provided during the deployment process. 4. **(Optional) Promote the Web Application**: - If you wish to move your application to production, you can promote it. Click on **Promote** under the **Deployment Area** section, then select **Confirm & Promote** when prompted. - Review the configurations and click **Execute** to finalize the promotion to production. For further details, you can refer to the complete documentation on deploying a web application here: [Deploy a Web Application](https://wso2.com/choreo/docs/tutorials/develop-a-single-page-web-application/#step-5-deploy-and-test-the-web-application). | O4: To deploy a web application in Choreo, follow these steps: 1. **Log in to Choreo**: - Go to the Choreo dashboard and log in with your credentials. 2. **Create a New Web Application**: - Click on the **"Create"** button. - Select **"Web Application"** from the options. 3. **Configure Your Web Application**: - Provide a name and description for your web application. - Choose the appropriate runtime environment (e.g., Node.js, Java, etc.). - Set up any necessary configurations, such as environment variables. 4. **Develop Your Application**: - Use the integrated code editor to write your application code. - You can also upload files or connect to a version control system (like Git) to pull your code. 5. **Set Up Dependencies**: - If your application requires external libraries or dependencies, specify them in the configuration settings. 6. **Test Your Application**: - Use the built-in testing tools to ensure your application is functioning as expected. 7. **Deploy the Application**: - Once you are satisfied with your application, click on the **"Deploy"** button. - Choose the deployment environment (e.g., development, production). 8. **Monitor the Deployment**: - After deployment, you can monitor the application’s performance and logs through the Choreo dashboard. 9. **Access Your Web Application**: - Once deployed, you will receive a URL to access your web application. For more detailed instructions and specific configurations, refer to the official Choreo documentation on [Deploying Web Applications](https://choreo.dev/docs/deploying-web-apps).
A5: 5 | B5: How can I test my service? | C5: To test your service in **Choreo**, you can use the integrated **OpenAPI Console** within the **Choreo Console UI**. Here are the detailed steps to perform the test: **Steps to Test the Service in Choreo Console** 1. **Navigate to the Test Console**: - In the **Choreo Console** left navigation menu, click **Test** and then click **Console**. 2. **Select the Environment**: - In the **OpenAPI Console** that opens, select **Development** from the environment drop-down list. 3. **Choose the Endpoint**: - In the **Endpoint** list, select the relevant **REST endpoint** for your service. 4. **Test the GET Method**: - Expand the **GET /** method (e.g., **GET /books**). - Click **Try it out**. - Click **Execute**. - Check the **Server Response** section to see the response from the server. 5. **Test the POST Method**: - Expand the **POST /** method (e.g., **POST /books**). - Click **Try it out**. - Update the **request body** with the necessary parameters. For example: ``` { ""author"": ""Your Author"", ""status"": ""to_read"", ""title"": ""Your Title"" } ``` - Click **Execute**. - Check the **Server Response** section. On successful invocation, you should receive a **201 HTTP status code**. 6. **Additional Methods**: - Similarly, you can expand and test other methods (e.g., **PUT**, **DELETE**) available for your service by following the **Try it out** and **Execute** steps. | D5: To test a service in Choreo, you can follow these steps within the Choreo Console: 1. **Access the Test Console**: - In the left navigation menu, click on **Test** and then select **Console**. 2. **Select the Environment**: - In the OpenAPI Console, choose **Development** from the environment drop-down menu. 3. **Choose the Endpoint**: - From the **Endpoint** list, select your service's REST endpoint (for example, a Books REST Endpoint). 4. **Test a Method**: - Expand the desired method you want to test, such as **GET /books**, and click on **Try it out**. 5. **Execute the Test**: - Click on **Execute** to send the request. 6. **Check the Response**: - Look at the **Server Response** section to see the results of your test. You can also explore other methods in the OpenAPI Console, such as **POST** or **DELETE**, depending on the functionality of your service. For more detailed instructions, you can refer to the documentation [here](https://wso2.com/choreo/docs/quick-start-guides/deploy-your-first-service/#step-4-test-the-service). | E5: Testing your service in Choreo is essential to ensure it works as expected. Here’s a step-by-step guide on how to do this: ### Step 1: Test in the Choreo Dashboard 1. **Log into Your Choreo Dashboard**: Access your Choreo account and go to the Dashboard where you manage your services. 2. **Test the Service Locally**: Choreo has tools for testing your service locally before deploying it. Use these tools for small-scale tests. ### Step 2: Use External Consumers (Simulated Calls) To test how your service behaves when it's integrated with external consumers, use Choreo’s built-in External Consumers feature. 1. **Navigate to External Consumers**: - Go to the Choreo Dashboard, then find "External Consumers" in the navigation menu. - This section allows you to create, view, update, and delete external consumer calls. 2. **Create a New External Consumer Call**: - Click on the "New External Consumer" button to start. - Configure the details of the external consumer call, including the service endpoint URL. 3. **Invoke and Test**: - After configuring the external consumer, you can invoke it. - See the response from the external consumer call directly within Choreo. ### Step 3: Deploy Your Service 1. **Deploy to Cloud**: - Ensure that your service deployment complies with Choreo’s best practices. - Review any necessary settings in Choreo for cloud deployment. 2. **Monitor Your Service**: - After deployment, use the Monitoring tool in Choreo to keep track of service performance and health. ### Step 4: Test Integration (Optional but Recommended) If your service needs to be integrated with another application, perform tests there as well: 1. **Integrate External System**: - Integrate your Choreo service with an external application. - Follow the steps for integration as described in Choreo’s documentation. 2. **Verify Communication**: - Ensure messages or data flow between the two systems as expected. For more detailed guidance and specific configurations, you may want to consult Choreo’s documentation pages: - [External Consumers in Choreo](https://docs.choreo.wso2.com/en/latest/administering/ext_consumers/) - [Deploying to Choreo Cloud](https://docs.choreo.wso2.com/en/latest/deploy-and-manage/services/deployments/) Feel free to explore more resources and support if you encounter any difficulties! | F5: To test your service in Choreo, you can use both the **Choreo DevOps** and **Test Cloud** environments. Below are the steps to deploy and test your service using these environments: ### Testing Your Service in Choreo DevOps Environment 1. **Deploy the Service**: Follow the steps to deploy your service to the Choreo DevOps environment. - Connect your GitHub repository, either through the UI or API. - Fill in the necessary details like display name, description, labels, color theme, etc. - Ensure that your service builds and deploys successfully. - Access your component in the **Project** section and click on **Test**. ![Test component](https://wso2.com/choreo/docs/assets/img/choreo-samples/test-component.png) 2. **Invoke the API**: In the **Test Configurations** pane, configure the endpoint as needed (e.g., production credentials for secure testing). You can specify parameters, headers, or JSON payloads to interact with the API. ![Configure endpoint](https://wso2.com/choreo/docs/assets/img/choreo-samples/configure-endpoint.png) 3. **Execute Tests**: Click **Run All** to execute tests against all endpoints. Alternatively, select an endpoint to run specific tests. 4. **View Test Results**: If any failures occur, they will be marked in red, providing feedback on how to troubleshoot. The results will list the tests performed along with their statuses. 5. **Log Level Tuning**: Adjust the log level in the **Logging & Monitoring** tab if the service generates more logs than expected. This prevents flooding the output with unnecessary log information during testing. ### Testing Your Service in Test Cloud Environment In addition to the Choreo DevOps environment, you can also test your components in the Test Cloud environment for further validation. #### Steps to Deploy Your Component in Test Cloud: 1. Sign in to the Choreo console. 2. From the top navigation menu, click **Organization**, select your organization. 3. Go to the left navigation menu and select **Components** then choose your component to view its card. 4. Under the **Create Version** card, click **Deploy**. 5. In the **Set Up** card, provide the necessary configuration details and deploy your component to the Test Cloud environment. For detailed guidance, refer to the documentation on [Testing Services](https://wso2.com/choreo/docs/testing/test-services/#test-the-service-in-the-choreo-cloud-data-plane). ### Additional Tips - Ensure that your service has appropriate permissions configured, especially if it interacts with other services. This involves assigning scopes during deployment. For a comprehensive understanding, please refer to the documentation here: [Test Components Manually](https://wso2.com/choreo/docs/testing/test-components-manually/#test-your-service). | G5: To test your service in Choreo, you have two primary options: **Testing the Service UI** and **Testing from the Console**. Let’s explore each option in detail. ### 1. Testing the Service UI When testing services using the Choreo console, you will primarily focus on visualizing service details through the Service page. The key activities involve: - Monitoring service requests and responses through the Request/Response pane. - Observing operational data like CPU and memory usage displayed on the Overview page. - Evaluating the logs and health status shown in the Logs section. - Analyzing service-level metrics found in the Diagnostics tab, including latency. - Checking for warning signs such as errors in the request/response pane and significant drops in the status of your service. Additionally, if you need to troubleshoot issues, you can use the Diagnostic view on the Service page to check for failed or errored operations. ### 2. Testing from the Console The Console also allows for testing the service by creating a connection with it using a connection cookie. You would specify the parameters and invoke a method, which can include passing a payload. This method provides both synchronous and asynchronous calls for service invocation. Here’s how to create a connection: - Click on the project under the **Overview** section in the left navigation menu. - Choose the component for which you want to create a connection, then navigate to **Test** > **Connection**. - Define your service details, which include the required parameters, optional parameters, and service endpoint details. - Click **Create** after filling in the details. ### Additional Tips for Effective Service Testing - Ensure that your service is deployed and ready for testing. - Make sure you have defined connections in the desired environment for testing purposes. - Test different parameters and payloads to evaluate the behavior of your service under various conditions. For more detailed instructions, you can refer to the following documentation links: - [Testing Services](https://wso2.com/choreo/docs/testing/test-services-with-choreo-test-runner/#testing-the-service-ui) - [Test Service Endpoints - Build, Deploy, and Test a Service in Choreo](https://wso2.com/choreo/docs/testing/test-service-endpoints/#test-the-service-while-it-is-running-in-choreo) These resources will help you effectively test and debug your services within the Choreo ecosystem. | H5: To test your service in Choreo, follow these steps: 1. **Deploy Your Service**: - Ensure your service is deployed in Choreo. This typically involves creating a service that exposes endpoints for various operations like GET, POST, etc. 2. **Create an API**: - Go to the Services tab in Choreo and select the service you want to test. - Click on the "Add API" button to create an API from the service. - Follow the prompts to configure the API. 3. **Configure API Endpoints**: - Map the service operations to API endpoints. This involves setting up the request and response mappings for each operation. - Test individual operations to ensure they work as expected. 4. **Set Up Webhooks** (Optional but useful for real-time testing): - If you need to trigger actions on other systems when a particular event occurs in your service, set up webhooks. - Configure webhooks to call back external systems with events or data. 5. **Test Using Postman or cURL**: - Use tools like Postman or execute cURL commands to send HTTP requests to your API endpoints. - For example, if your API has a `GET` endpoint to fetch data, use the following command in your terminal: ```bash curl -X GET "https://api.example.com/data" ``` - Alternatively, you can use Postman to construct and send requests. 6. **Use the Built-in Tester**: - Navigate to the "Test" tab of the API you created. - Choose the operation you want to test. - Fill in any required fields and click the "Test" button. - Check the console output for any errors and verify the response. 7. **Monitor with Observability Tools**: - Enable logging and observability features in your service. - Monitor logs and metrics to check if the service behaves as expected under load and different conditions. 8. **Perform Security Testing**: - Verify that your API security settings are correctly configured. - Test with both valid and invalid credentials if applicable. - Check rate limiting, throttling, and authentication mechanisms. 9. **Load Testing**: - Once satisfied with single-user testing, perform load testing to see how the service handles multiple concurrent requests. - Tools like JMeter can be used to simulate high traffic scenarios. For detailed guidance, refer to the official Choreo documentation on: - [Creating and Configuring APIs](https://wso2.com/choreo/apis/) - [Testing APIs](https://wso2.com/choreo/api-testing/) - [Security Testing](https://wso2.com/choreo/api-security/) If you run into specific issues, make sure to provide error messages or describe the problem in detail so I can offer more targeted advice. | I5: To effectively test a service in Choreo, you can follow several approaches depending on your specific requirements and the nature of your service: ### 1. **Manual Testing** - This involves invoking your component manually from the [Component Listing](https://devportal.choreo.dev/choreo/applications/{application-id}/components) page to verify its functionality. - Steps: 1. Navigate to the **Component Listing**. 2. Click on the desired component to open the **Overview** page. 3. Use the **Try it Out** option under the desired endpoint to test it directly. ### 2. **Integration Testing via the Choreo Console** - Utilize the Choreo Console to facilitate automated testing of service components. - This allows for testing the interactions between different services efficiently. - Note that integration tests can run on specific environments (Development, Staging, Production). ### 3. **Creating a Dedicated Test Component** - Develop a dedicated component solely for testing purposes within your Choreo project. - This approach helps isolate testing activities, ensuring they do not interfere with production systems. ### 4. **API Management Testing** - For API management, focus on validating endpoint functionalities, response statuses, latency, security features, and error conditions during testing. - Ensure that the API behavior meets expectations across different scenarios. ### 5. **Observability Insights** - Monitor your services using the observability insights in Choreo, which include logs, usage patterns, latency details, errors, and warnings. - This data can significantly enhance your testing process by providing real-time feedback. By combining these methods, you can thoroughly test your services in various scenarios and ensure their reliability. For more detailed steps and guidelines, please refer to the [Testing Services and Components Documentation](https://wso2.com/choreo/docs/testing/test-services-and-components/) in the Choreo documentation. | J5: To test a service in Choreo effectively, you can follow these steps and best practices: ### Step-by-Step Guide to Test Your Service in Choreo 1. **Access the Component**: - In the **Component Listing** pane, click on the component you want to test. 2. **Navigate to Testing**: - On the left navigation menu, click on **Test**. 3. **Choose Environment and Deployment Track**: - In the **Test** pane, select the appropriate environment from the drop-down list. - Select the relevant deployment track or version that you wish to test. 4. **Create a New Test Request**: - Click **+ Create** to start setting up your testing scenario. 5. **Set Up Test Parameters**: - Enter the required parameters based on your component type in the **Test Parameters** pane. - Click **Next**. 6. **Execute Your Tests**: - If applicable, you may provide values for additional test parameters in the respective sections. - Click **Execute**. This will trigger a series of tests: - **Schema Validation**: The request payload is validated against the OpenAPI specification. - **Security Context**: The context is injected to generate a call based on the specified protocol (REST or GraphQL). - **Request Handling**: Depending on the endpoint type, your application receives the request, and a response is generated and sent back through the test proxy. 7. **View Execution Results**: - After executing the test, you will see the execution results listed under the **Runbook** tab. Here, you can view response counts and failure rates. ### Best Practices for Testing Services - **Use Relative URLs**: For REST API endpoints, it's advisable to use relative URLs since they do not include a server host. - **Check API Definitions**: Ensure that your service is fully defined in Choreo, including parameters and body fields that must match the service’s implementation. - **Test Different Scenarios**: Run various test cases, including edge cases, to validate the service’s behavior across different scenarios - **Automated Testing**: If applicable, integrate automated testing into your workflow using tools like GitLab CI/CD for continuous integration. For more detailed information, you can refer to the documentation here: [Test a Service](https://wso2.com/choreo/docs/testing/test-a-service/) and [Testing Overview](https://wso2.com/choreo/docs/testing/test-services-and-integrations/). | O5: To test your service in Choreo, you can follow these steps: 1. **Access the Choreo Dashboard**: - Log in to your Choreo account and navigate to the dashboard. 2. **Select Your Service**: - From the dashboard, locate and select the service you want to test. 3. **Use the Test Feature**: - In the service details view, look for the "Test" option. This feature allows you to invoke your service directly from the dashboard. 4. **Configure Test Parameters**: - If your service requires input parameters, configure them in the test interface. You can specify the request body, headers, and any query parameters as needed. 5. **Execute the Test**: - Click on the "Test" button to send the request to your service. 6. **Review the Response**: - After executing the test, review the response returned by your service. This will include the status code, response body, and any headers. 7. **Debugging**: - If the response is not as expected, check the logs for any errors or issues. You can access logs through the observability features in Choreo. 8. **Iterate**: - Make any necessary adjustments to your service based on the test results and repeat the testing process as needed. For more detailed information, you can refer to the official Choreo documentation on [Testing Services](https://choreo.dev/docs/develop/testing-services).
